usage: linear_eval.py [-h] [--train_type TRAIN_TYPE] [--finetune FINETUNE]
                      [--epochwise EPOCHWISE] [--ss SS] [--trans TRANS]
                      [--clean CLEAN] [--adv_img ADV_IMG] [--lr LR]
                      [--lr_multiplier LR_MULTIPLIER] [--dataset DATASET]
                      [--load_checkpoint LOAD_CHECKPOINT] [--model MODEL]
                      [--name NAME] [--seed SEED] [--batch-size BATCH_SIZE]
                      [--epoch EPOCH]
                      [--color_jitter_strength COLOR_JITTER_STRENGTH]
                      [--temperature TEMPERATURE] [--local_rank LOCAL_RANK]
                      [--ngpu NGPU] [--min MIN] [--max MAX]
                      [--attack_type ATTACK_TYPE] [--epsilon EPSILON]
                      [--alpha ALPHA] [--k K] [--random_start RANDOM_START]
linear_eval.py: error: argument --lr: invalid float value: 'dataset=cifar-10'
Traceback (most recent call last):
  File "/opt/conda/lib/python3.8/runpy.py", line 194, in _run_module_as_main
    return _run_code(code, main_globals, None,
  File "/opt/conda/lib/python3.8/runpy.py", line 87, in _run_code
    exec(code, run_globals)
  File "/opt/conda/lib/python3.8/site-packages/torch/distributed/launch.py", line 340, in <module>
    main()
  File "/opt/conda/lib/python3.8/site-packages/torch/distributed/launch.py", line 326, in main
    sigkill_handler(signal.SIGTERM, None)  # not coming back
  File "/opt/conda/lib/python3.8/site-packages/torch/distributed/launch.py", line 301, in sigkill_handler
    raise subprocess.CalledProcessError(returncode=last_return_code, cmd=cmd)
subprocess.CalledProcessError: Command '['/opt/conda/bin/python', '-u', 'linear_eval.py', '--local_rank=0', '--ngpu', '1', '--batch-size=1024', '--train_type=linear_eval', '--model=0.1', '--epoch', '150', '--lr', 'dataset=cifar-10', '--name', 'type=ResNet18', '--load_checkpoint=ckpt.t7Rep_attack_ep_0.0314_alpha_0.007_min_val_0.0_max_val_1.0_max_iters_7_type_linf_randomstart_Truecontrastive_ResNet18_cifar-10_b256_nGPU1_l256_0', '--clean=True', '--dataset=', '--seed=']' returned non-zero exit status 2.
usage: robustness_test.py [-h] [--train_type TRAIN_TYPE] [--dataset DATASET]
                          [--load_checkpoint LOAD_CHECKPOINT] [--model MODEL]
                          [--name NAME] [--seed SEED]
                          [--batch-size BATCH_SIZE]
                          [--color_jitter_strength COLOR_JITTER_STRENGTH]
                          [--temperature TEMPERATURE]
                          [--local_rank LOCAL_RANK] [--ngpu NGPU]
                          [--attack_type ATTACK_TYPE] [--epsilon EPSILON]
                          [--alpha ALPHA] [--k K]
                          [--random_start RANDOM_START]
robustness_test.py: error: argument --seed: invalid int value: ''
Traceback (most recent call last):
  File "/opt/conda/lib/python3.8/runpy.py", line 194, in _run_module_as_main
    return _run_code(code, main_globals, None,
  File "/opt/conda/lib/python3.8/runpy.py", line 87, in _run_code
    exec(code, run_globals)
  File "/opt/conda/lib/python3.8/site-packages/torch/distributed/launch.py", line 340, in <module>
    main()
  File "/opt/conda/lib/python3.8/site-packages/torch/distributed/launch.py", line 326, in main
    sigkill_handler(signal.SIGTERM, None)  # not coming back
  File "/opt/conda/lib/python3.8/site-packages/torch/distributed/launch.py", line 301, in sigkill_handler
    raise subprocess.CalledProcessError(returncode=last_return_code, cmd=cmd)
subprocess.CalledProcessError: Command '['/opt/conda/bin/python', '-u', 'robustness_test.py', '--local_rank=0', '--ngpu', '1', '--train_type=linear_eval', '--name=type=ResNet18', '--batch-size=1024', '--model=0.1', '--load_checkpoint=../checkpoint/ckpt.t7type=ResNet18_Evaluate_linear_eval_ResNet18__', '--attack_type=linf', '--epsilon=0.0314', '--alpha=0.00314', '--k=20', '--module', '--dataset=', '--seed=']' returned non-zero exit status 2.
usage: robustness_test.py [-h] [--train_type TRAIN_TYPE] [--dataset DATASET]
                          [--load_checkpoint LOAD_CHECKPOINT] [--model MODEL]
                          [--name NAME] [--seed SEED]
                          [--batch-size BATCH_SIZE]
                          [--color_jitter_strength COLOR_JITTER_STRENGTH]
                          [--temperature TEMPERATURE]
                          [--local_rank LOCAL_RANK] [--ngpu NGPU]
                          [--attack_type ATTACK_TYPE] [--epsilon EPSILON]
                          [--alpha ALPHA] [--k K]
                          [--random_start RANDOM_START]
robustness_test.py: error: argument --seed: invalid int value: ''
Traceback (most recent call last):
  File "/opt/conda/lib/python3.8/runpy.py", line 194, in _run_module_as_main
    return _run_code(code, main_globals, None,
  File "/opt/conda/lib/python3.8/runpy.py", line 87, in _run_code
    exec(code, run_globals)
  File "/opt/conda/lib/python3.8/site-packages/torch/distributed/launch.py", line 340, in <module>
    main()
  File "/opt/conda/lib/python3.8/site-packages/torch/distributed/launch.py", line 326, in main
    sigkill_handler(signal.SIGTERM, None)  # not coming back
  File "/opt/conda/lib/python3.8/site-packages/torch/distributed/launch.py", line 301, in sigkill_handler
    raise subprocess.CalledProcessError(returncode=last_return_code, cmd=cmd)
subprocess.CalledProcessError: Command '['/opt/conda/bin/python', '-u', 'robustness_test.py', '--local_rank=0', '--ngpu', '1', '--train_type=linear_eval', '--name=type=ResNet18', '--batch-size=1024', '--model=0.1', '--load_checkpoint=../checkpoint/ckpt.t7type=ResNet18_Evaluate_linear_eval_ResNet18__', '--attack_type=linf', '--epsilon=0.0627', '--alpha=0.00627', '--k=20', '--module', '--dataset=', '--seed=']' returned non-zero exit status 2.
