usage: linear_eval.py [-h] [--train_type TRAIN_TYPE] [--finetune FINETUNE]
                      [--epochwise EPOCHWISE] [--ss SS] [--trans TRANS]
                      [--clean CLEAN] [--adv_img ADV_IMG] [--lr LR]
                      [--lr_multiplier LR_MULTIPLIER] [--dataset DATASET]
                      [--load_checkpoint LOAD_CHECKPOINT] [--model MODEL]
                      [--name NAME] [--seed SEED] [--batch-size BATCH_SIZE]
                      [--epoch EPOCH]
                      [--color_jitter_strength COLOR_JITTER_STRENGTH]
                      [--temperature TEMPERATURE] [--local_rank LOCAL_RANK]
                      [--ngpu NGPU] [--min MIN] [--max MAX]
                      [--attack_type ATTACK_TYPE] [--epsilon EPSILON]
                      [--alpha ALPHA] [--k K] [--random_start RANDOM_START]
linear_eval.py: error: unrecognized arguments: --#load_checkpoint=ckpt_300epochs.t7
Traceback (most recent call last):
  File "/opt/conda/lib/python3.8/runpy.py", line 194, in _run_module_as_main
    return _run_code(code, main_globals, None,
  File "/opt/conda/lib/python3.8/runpy.py", line 87, in _run_code
    exec(code, run_globals)
  File "/opt/conda/lib/python3.8/site-packages/torch/distributed/launch.py", line 340, in <module>
    main()
  File "/opt/conda/lib/python3.8/site-packages/torch/distributed/launch.py", line 326, in main
    sigkill_handler(signal.SIGTERM, None)  # not coming back
  File "/opt/conda/lib/python3.8/site-packages/torch/distributed/launch.py", line 301, in sigkill_handler
    raise subprocess.CalledProcessError(returncode=last_return_code, cmd=cmd)
subprocess.CalledProcessError: Command '['/opt/conda/bin/python', '-u', 'linear_eval.py', '--local_rank=0', '--ngpu', '1', '--batch-size=1024', '--train_type=linear_eval', '--model=ResNet18', '--epoch', '150', '--lr', '0.1', '--name', 'random_name', '--#load_checkpoint=ckpt_300epochs.t7', '--clean=True', '--dataset=cifar-10', '--seed=7']' returned non-zero exit status 2.
